Workbook

Sheet Microinformatica
F1: INFORMACION USUARIO EQUIPO ASIGNADO | O1: SOLO INFORMACION DEL EMPLEADO RESPONSABLE DE FEDERACION/ALMACAFE
A2: EMPRESA PROPIETARIO DEL EQUIPO | B2: DEPENDENCIA | C2: FUENTE DE RECURSO | D2: EMPRESA FUNCIONARIO | E2: EMPLEADO O CONTRATISTA | F2: CEDULA DEL FUNCIONARIO/CONTRATISTA | G2: SHORTNAME | H2: NOMBRES Y APELLIDOS | I2: DEPARTAMENTO | J2: CIUDAD | K2: CARGO | L2: ÁREA | M2: UBICACIÓN Y PISO | N2: TIPO DE RECURSO | O2: CEDULA | P2: NOMBRES Y APELLIDOS | Q2: CARGO | R2: CIUDAD | S2: AREA | T2: TIPO DE RECURSO | U2: TIPO | V2: SERIAL | W2: PLACA | X2: MARCA | Y2: MODELO | Z2: NOMBRE DE EQUIPO | AA2: ESTADO OPERATIVO | AB2: RAZÓN DEL ESTADO | AC2: ADMINISTRADO/CONTROLADO | AD2: PROCESADOR | AE2: MEMORIA RAM | AF2: TAMAÑO DISCO DURO | AG2: SISTEMA OPERATIVO | AH2: FECHA DE COMPRA | AI2: FIN DE GARANTIA | AJ2: TIEMPO USO (AÑOS) | AK2: TIPO DE PROPIEDAD | AL2: CHEKLIST (RESPONSABLE TI) | AM2: ORDEN DE REMISIÓN | AN2: OBSERVACIONES | AO2: TIPO DE PERFIL | AP2: TIPO DE EQUIPO | AQ2: TIPO DE RECURSO | AR2: CRUCE AV 23-12-2025 | AS2: Cruce Shortname | AT2: Resultado cruce AV
A3: FEDERACIÓN | B3: SUCURSAL IBAGUE | C3: FON1 | D3: FEDERACIÓN | E3: EMPLEADO | F3: 93370510 | G3: 93370510 | H3: ALEXANDER POLO PRIETO | I3: TOLIMA | J3: IBAGUE | K3: EXTENSIONISTA | L3: SECCIONAL IBAGUE | M3: 2 | N3: RECURSO PROPIO | O3: N/A | P3: N/A | Q3: N/A | R3: N/A | S3: N/A | U3: EQUIPO PORTATIL | V3: 9QH8SW3 | W3: F101875 | X3: DELL | Y3: Latitude 5450 | Z3: L11FETOLAPOL01 | AA3: EN OPERACION | AB3: ASIGNACION RESPONSABLE | AC3: CONTROLADO | AD3: Ultra 5 125u | AE3: 16GB | AF3: 500GB | AG3: WINDOWS 11 PRO | AH3: 45670 | AI3: 47497 | AJ3: =FLOOR(YEARFRAC(AH3, TODAY(), 1),1) -> 1 | AL3: JHONATHAN ARMANDO CAMARGO IZQUIERDO | AN3: N/A | AO3: N/A | AP3: N/A | AQ3: N/A | AR3: {=IFERROR(XLOOKUP(V3,'AV 23-12-2025'!A:A,'AV 23-12-2025'!D:D),"zz.No cruza con AV")} -> 19/12/25 5:24:37 COT | AS3: {=IFERROR(XLOOKUP(V3,'AV 23-12-2025'!A:A,'AV 23-12-2025'!C:C), "No cruza con AV")} -> ALEXANDER POLO | AT3: Si cruza con Antivirus
A4: FEDERACIÓN | B4: SUCURSAL IBAGUE | C4: FON1 | D4: FEDERACIÓN | E4: EMPLEADO | F4: 79912904 | H4: JAVIER LEONARDO MESA TRUJILLO | I4: TOLIMA | J4: IBAGUE | K4: ANALISTA | L4: PROYECTOS | M4: 2 | N4: RECURSO PROPIO | O4: N/A | P4: N/A | Q4: N/A | R4: N/A | S4: N/A | U4: EQUIPO ESCRITORIO | V4: 1NFPT64 | W4: 10105258 | X4: DELL | Y4: OPTIPLEX d15u MICRO 7020 | Z4: L11FETOLJMEZ01 | AA4: EN OPERACION | AB4: ASIGNACION RESPONSABLE | AC4: CONTROLADO | AD4: I7-14700t | AE4: 16GB | AF4: 500GB | AG4: WINDOWS 11 PRO | AH4: 45692 | AI4: 46882 | AJ4: =FLOOR(YEARFRAC(AH4, TODAY(), 1),1) -> 1 | AL4: JHONATHAN ARMANDO CAMARGO IZQUIERDO | AN4: N/A | AO4: N/A | AP4: N/A | AQ4: N/A | AR4: {=IFERROR(XLOOKUP(V4,'AV 23-12-2025'!A:A,'AV 23-12-2025'!D:D),"zz.No cruza con AV")} -> 23/12/25 7:38:03 COT | AS4: {=IFERROR(XLOOKUP(V4,'AV 23-12-2025'!A:A,'AV 23-12-2025'!C:C), "No cruza con AV")} -> JAVIER MEZA | AT4: Si cruza con Antivirus
A5: FEDERACIÓN | B5: SUCURSAL IBAGUE | C5: FON1 | D5: FEDERACIÓN | E5: EMPLEADO | F5: 1006118164 | H5: GISED CAMILA TOVAR ASCENCIO | I5: TOLIMA | J5: IBAGUE | K5: PROMOTOR DESARROLLO RURAL | L5: GOBERNACION DEL TOLIMA | M5: 2 | N5: RECURSO PROPIO | O5: N/A | P5: N/A | Q5: N/A | R5: N/A | S5: N/A | U5: EQUIPO PORTATIL | V5: BPLQ824 | W5: 10104244 | X5: DELL | Y5: Latitude 3440 | Z5: L11FETOLJDE3 | AA5: EN OPERACION | AB5: ASIGNACION RESPONSABLE | AC5: CONTROLADO | AD5: I5-1335u | AE5: 16GB | AF5: 500GB | AG5: WINDOWS 11 PRO | AH5: 45435 | AI5: 45946 | AJ5: =FLOOR(YEARFRAC(AH5, TODAY(), 1),1) -> 1 | AL5: JHONATHAN ARMANDO CAMARGO IZQUIERDO | AN5: N/A | AO5: N/A | AP5: N/A | AQ5: N/A | AR5: {=IFERROR(XLOOKUP(V5,'AV 23-12-2025'!A:A,'AV 23-12-2025'!D:D),"zz.No cruza con AV")} -> 19/12/25 12:26:35 COT | AS5: {=IFERROR(XLOOKUP(V5,'AV 23-12-2025'!A:A,'AV 23-12-2025'!C:C), "No cruza con AV")} -> JDE3 | AT5: Si cruza con Antivirus
A6: FEDERACIÓN | B6: SUCURSAL IBAGUE | C6: FON1 | D6: FEDERACIÓN | E6: EMPLEADO | F6: 5825253 | G6: 5825253 | H6: JORGE ELIECER CALDERON VILLAMIL | I6: TOLIMA | J6: IBAGUE | K6: COORDINADOR PROGRAMA | L6: PROGRAMA INVESTIGACION PARTICIPATIVA | M6: 2 | N6: RECURSO PROPIO | O6: N/A | P6: N/A | Q6: N/A | R6: N/A | S6: N/A | U6: EQUIPO PORTATIL | V6: B419SW3 | W6: F101887 | X6: DELL | Y6: Latitude 5450 | Z6: L11FETOLJCAL01 | AA6: EN OPERACION | AB6: ASIGNACION RESPONSABLE | AC6: CONTROLADO | AD6: Ultra 5 125u | AE6: 16GB | AF6: 500GB | AG6: WINDOWS 11 PRO | AH6: 45596 | AI6: 47497 | AJ6: =FLOOR(YEARFRAC(AH6, TODAY(), 1),1) -> 1 | AL6: JHONATHAN ARMANDO CAMARGO IZQUIERDO | AN6: N/A | AO6: N/A | AP6: N/A | AQ6: N/A | AR6: {=IFERROR(XLOOKUP(V6,'AV 23-12-2025'!A:A,'AV 23-12-2025'!D:D),"zz.No cruza con AV")} -> 23/12/25 12:37:17 COT | AS6: {=IFERROR(XLOOKUP(V6,'AV 23-12-2025'!A:A,'AV 23-12-2025'!C:C), "No cruza con AV")} -> JORGE CALDERON | AT6: Si cruza con Antivirus
A7: FEDERACIÓN | B7: SUCURSAL IBAGUE | C7: FON1 | D7: FEDERACIÓN | E7: EMPLEADO | F7: 1005692507 | G7: JVALENC507 | H7: JUANITA VALENCIA GARCIA | I7: TOLIMA | J7: IBAGUE | K7: AUXILIAR ADMINISTRATIVO | L7: ADMINISTRATIVOS | M7: 2 | N7: RECURSO PROPIO | O7: N/A | P7: N/A | Q7: N/A | R7: N/A | S7: N/A | U7: EQUIPO PORTATIL | V7: BW43B44 | W7: 10104274 | X7: DELL | Y7: Latitude 3440 | Z7: W11FETOL | AA7: EN OPERACION | AB7: ASIGNACION RESPONSABLE | AC7: CONTROLADO | AD7: I5-1235u | AE7: 16GB | AF7: 500GB | AG7: WINDOWS 11 PRO | AH7: 45537 | AI7: 45955 | AJ7: =FLOOR(YEARFRAC(AH7, TODAY(), 1),1) -> 1 | AL7: JHONATHAN ARMANDO CAMARGO IZQUIERDO | AN7: N/A | AO7: N/A | AP7: N/A | AQ7: N/A | AR7: {=IFERROR(XLOOKUP(V7,'AV 23-12-2025'!A:A,'AV 23-12-2025'!D:D),"zz.No cruza con AV")} -> zz.No cruza con AV | AS7: {=IFERROR(XLOOKUP(V7,'AV 23-12-2025'!A:A,'AV 23-12-2025'!C:C), "No cruza con AV")} -> No cruza con AV | AT7: No cruza con Antivirus
A8: FEDERACIÓN | B8: SUCURSAL IBAGUE | C8: FON1 | D8: FEDERACIÓN | E8: EMPLEADO | F8: 38210802 | G8: YBONILL802 | H8: YENNY PAOLA BONILLA ROJAS | I8: TOLIMA | J8: IBAGUE | K8: COORDINADOR ADMINISTRATIVO | L8: ADMINISTRATIVOS | M8: 2 | N8: RECURSO PROPIO | O8: N/A | P8: N/A | Q8: N/A | R8: N/A | S8: N/A | U8: EQUIPO ESCRITORIO | V8: 8QN0Y14 | W8: 10104277 | X8: DELL | Y8: OPTIPLEX Micro 7010 | Z8: D11FETOLYBON01 | AA8: EN OPERACION | AB8: ASIGNACION RESPONSABLE | AC8: CONTROLADO | AD8: I5-13500t | AE8: 16GB | AF8: 500GB | AG8: WINDOWS 11 PRO | AH8: 45405 | AI8: 46690 | AJ8: =FLOOR(YEARFRAC(AH8, TODAY(), 1),1) -> 1 | AL8: JHONATHAN ARMANDO CAMARGO IZQUIERDO | AN8: N/A | AO8: N/A | AP8: N/A | AQ8: N/A | AR8: {=IFERROR(XLOOKUP(V8,'AV 23-12-2025'!A:A,'AV 23-12-2025'!D:D),"zz.No cruza con AV")} -> 23/12/25 12:07:37 COT | AS8: {=IFERROR(XLOOKUP(V8,'AV 23-12-2025'!A:A,'AV 23-12-2025'!C:C), "No cruza con AV")} -> Paola Bonilla | AT8: Si cruza con Antivirus
A9: FEDERACIÓN | B9: SUCURSAL IBAGUE | C9: FON1 | D9: FEDERACIÓN | E9: EMPLEADO | F9: 65771971 | H9: JENNY TORRES ARANGO | I9: TOLIMA | J9: IBAGUE | K9: TESORERO AUXILIAR | L9: TESORERIA | M9: 2 | N9: RECURSO PROPIO | O9: N/A | P9: N/A | Q9: N/A | R9: N/A | S9: N/A | U9: EQUIPO ESCRITORIO | V9: 400SN40088 | W9: 10099137 | X9: COMPUMAX | Y9: 1052-900-0078 | Z9: W11FETOLJTOR | AA9: EN OPERACION | AB9: ASIGNACION RESPONSABLE | AC9: CONTROLADO | AD9: I5-11400 | AE9: 16GB | AF9: 500GB | AG9: WINDOWS 11 PRO | AH9: 45087 | AI9: NO REGISTRA | AJ9: =FLOOR(YEARFRAC(AH9, TODAY(), 1),1) -> 2 | AL9: JHONATHAN ARMANDO CAMARGO IZQUIERDO | AN9: N/A | AO9: N/A | AP9: N/A | AQ9: N/A | AR9: {=IFERROR(XLOOKUP(V9,'AV 23-12-2025'!A:A,'AV 23-12-2025'!D:D),"zz.No cruza con AV")} -> 23/12/25 12:15:23 COT | AS9: {=IFERROR(XLOOKUP(V9,'AV 23-12-2025'!A:A,'AV 23-12-2025'!C:C), "No cruza con AV")} -> Jenny Torres | AT9: Si cruza con Antivirus
A10: FEDERACIÓN | B10: SUCURSAL IBAGUE | C10: FON1 | D10: FEDERACIÓN | E10: EMPLEADO | F10: 1053767215 | G10: JHINCAP215 | H10: JULIAN DAVID HINCAPIE BETANCUR | I10: TOLIMA | J10: IBAGUE | K10: LIDER DEPARTAMENTAL EXTENSION RURAL | L10: EXTENSION RURAL | M10: 2 | N10: RECURSO PROPIO | O10: N/A | P10: N/A | Q10: N/A | R10: N/A | S10: N/A | U10: EQUIPO ESCRITORIO | V10: J517XV3 | W10: 10101123 | X10: DELL | Y10: OPTIPLEX 7010 d15u | Z10: L11FETOLJHIN01 | AA10: EN OPERACION | AB10: ASIGNACION RESPONSABLE | AC10: CONTROLADO | AD10: I5-13500t | AE10: 8GB | AF10: 500GB | AG10: WINDOWS 11 PRO | AH10: 45097 | AI10: 46343 | AJ10: =FLOOR(YEARFRAC(AH10, TODAY(), 1),1) -> 2 | AL10: JHONATHAN ARMANDO CAMARGO IZQUIERDO | AN10: N/A | AO10: N/A | AP10: N/A | AQ10: N/A | AR10: {=IFERROR(XLOOKUP(V10,'AV 23-12-2025'!A:A,'AV 23-12-2025'!D:D),"zz.No cruza con AV")} -> zz.No cruza con AV | AS10: {=IFERROR(XLOOKUP(V10,'AV 23-12-2025'!A:A,'AV 23-12-2025'!C:C), "No cruza con AV")} -> No cruza con AV | AT10: No cruza con Antivirus
A11: FEDERACIÓN | B11: SUCURSAL IBAGUE | C11: FON1 | D11: FEDERACIÓN | E11: EMPLEADO | F11: 28559149 | G11: FESGUE | H11: SVETLANY GUEPENDO ORTIZ | I11: TOLIMA | J11: IBAGUE | K11: ANALISTA | L11: EXTENSION RURAL | M11: 2 | N11: RECURSO PROPIO | O11: N/A | P11: N/A | Q11: N/A | R11: N/A | S11: N/A | U11: EQUIPO ESCRITORIO | V11: 1617XV3 | W11: 1010178 | X11: DELL | Y11: OPTIPLEX MICRO 7010 | Z11: D11FETOLSGUE01 | AA11: EN OPERACION | AB11: ASIGNACION RESPONSABLE | AC11: CONTROLADO | AD11: I3 | AE11: 8GB | AF11: 250GB | AG11: WINDOWS 11 PRO | AH11: 45097 | AI11: 46343 | AJ11: =FLOOR(YEARFRAC(AH11, TODAY(), 1),1) -> 2 | AL11: JHONATHAN ARMANDO CAMARGO IZQUIERDO | AN11: N/A | AO11: N/A | AP11: N/A | AQ11: N/A | AR11: {=IFERROR(XLOOKUP(V11,'AV 23-12-2025'!A:A,'AV 23-12-2025'!D:D),"zz.No cruza con AV")} -> 19/12/25 14:42:28 COT | AS11: {=IFERROR(XLOOKUP(V11,'AV 23-12-2025'!A:A,'AV 23-12-2025'!C:C), "No cruza con AV")} -> Svetlany Guependo | AT11: Si cruza con Antivirus
A12: FEDERACIÓN | B12: SUCURSAL IBAGUE | C12: FON1 | D12: FEDERACIÓN | E12: EMPLEADO | F12: 1007790166 | H12: YINA PAOLA OLAVE ANDRADE | I12: TOLIMA | J12: IBAGUE | K12: AUXILIAR ADMINISTRATIVO | L12: SECCIONAL IBAGUE | M12: 2 | N12: RECURSO PROPIO | O12: N/A | P12: N/A | Q12: N/A | R12: N/A | S12: N/A | U12: EQUIPO ESCRITORIO | V12: F717XV3 | W12: F717xv3CAMBIAR | X12: DELL | Y12: OPTIPLEX Micro 7010 | Z12: D11FETOLYOLA01 | AA12: EN OPERACION | AB12: ASIGNACION RESPONSABLE | AC12: CONTROLADO | AD12: I5-13500t | AE12: 16GB | AF12: 500GB | AG12: WINDOWS 11 PRO | AH12: 45097 | AI12: 46343 | AJ12: =FLOOR(YEARFRAC(AH12, TODAY(), 1),1) -> 2 | AL12: JHONATHAN ARMANDO CAMARGO IZQUIERDO | AN12: N/A | AO12: N/A | AP12: N/A | AQ12: N/A | AR12: {=IFERROR(XLOOKUP(V12,'AV 23-12-2025'!A:A,'AV 23-12-2025'!D:D),"zz.No cruza con AV")} -> 18/12/25 16:27:54 COT | AS12: {=IFERROR(XLOOKUP(V12,'AV 23-12-2025'!A:A,'AV 23-12-2025'!C:C), "No cruza con AV")} -> Yina Olave | AT12: Si cruza con Antivirus
A13: FEDERACIÓN | B13: SUCURSAL IBAGUE | C13: FON1 | D13: FEDERACIÓN | E13: EMPLEADO | F13: 1110541614 | G13: JCAMARG614 | H13: JHONATHAN ARMANDO CAMARGO IZQUIERDO | I13: TOLIMA | J13: IBAGUE | K13: ANALISTA TIC | L13: TIC | M13: 2 | N13: RECURSO PROPIO | O13: N/A | P13: N/A | Q13: N/A | R13: N/A | S13: N/A | U13: EQUIPO ESCRITORIO | V13: 8517XV3 | W13: 10101201 | X13: DELL | Y13: OPTIPLEX MICRO 7010 | Z13: No Aplica | AA13: ALMACENADO | AB13: ALISTAMIENTO/SOPORTE | AC13: CONTROLADO | AD13: Core i5 10 | AE13: 8GB | AF13: 512GB | AG13: No Aplica | AH13: 45097 | AI13: 46343 | AJ13: =FLOOR(YEARFRAC(AH13, TODAY(), 1),1) -> 2 | AL13: JHONATHAN ARMANDO CAMARGO IZQUIERDO | AN13: SIN USUARIO - PARA DESBLOQUEAR BIOS | AO13: N/A | AP13: N/A | AQ13: N/A | AR13: {=IFERROR(XLOOKUP(V13,'AV 23-12-2025'!A:A,'AV 23-12-2025'!D:D),"zz.No cruza con AV")} -> 10/05/25 11:49:29 COT | AS13: {=IFERROR(XLOOKUP(V13,'AV 23-12-2025'!A:A,'AV 23-12-2025'!C:C), "No cruza con AV")} -> Ingrid Segura | AT13: Si cruza con Antivirus
A14: FEDERACIÓN | B14: SUCURSAL IBAGUE | C14: FON1 | D14: FEDERACIÓN | E14: EMPLEADO | F14: 1105335001 | H14: JULIAN ANDRES LEITON CARDENAS | I14: TOLIMA | J14: IBAGUE | K14: PROFESIONAL DESARROLLO SOCIAL | L14: DESARROLLO SOCIAL | M14: 2 | N14: RECURSO PROPIO | O14: N/A | P14: N/A | Q14: N/A | R14: N/A | S14: N/A | U14: EQUIPO PORTATIL | V14: 1FBVYH3 | W14: 10095976 | X14: DELL | Y14: Vostro 3400 | Z14: L11FETOLJULIANLEITON | AA14: EN OPERACION | AB14: ASIGNACION RESPONSABLE | AC14: CONTROLADO | AD14: I5-1135g7 | AE14: 16GB | AF14: 500GB | AG14: WINDOWS 11 PRO | AH14: 44540 | AI14: 44959 | AJ14: =FLOOR(YEARFRAC(AH14, TODAY(), 1),1) -> 4 | AL14: JHONATHAN ARMANDO CAMARGO IZQUIERDO | AN14: N/A | AO14: N/A | AP14: N/A | AQ14: N/A | AR14: {=IFERROR(XLOOKUP(V14,'AV 23-12-2025'!A:A,'AV 23-12-2025'!D:D),"zz.No cruza con AV")} -> 1/10/25 16:34:19 COT | AS14: {=IFERROR(XLOOKUP(V14,'AV 23-12-2025'!A:A,'AV 23-12-2025'!C:C), "No cruza con AV")} -> Julian Leiton | AT14: Si cruza con Antivirus
A15: FEDERACIÓN | B15: SUCURSAL IBAGUE | C15: FON1 | D15: FEDERACIÓN | E15: CONTRATISTA | F15: 1110575083 | G15: ADIAZ083 | H15: ANGIE PAOLA DIAZ MORA | I15: TOLIMA | J15: IBAGUE | K15: AUXILIAR ADMINISTRATIVO | L15: BENEFICIO ECOLOGICO | M15: 2 | N15: RECURSO PROPIO | O15: 1110585547 | P15: GERMAN CAMILO ROMERO MOSQUERA | Q15: COORDINADOR BENEFICIO ECOLOGICO | R15: IBAGUE | S15: BENEFICIO ECOLOGICO | T15: RECURSO PROPIO | U15: EQUIPO PORTATIL | V15: 8VVJS93 | W15: 10105240 | X15: DELL | Y15: Latitude 3420 | Z15: L11FETOLCRED1 | AA15: EN OPERACION | AB15: ASIGNACION RESPONSABLE | AC15: CONTROLADO | AD15: I3-1115g4 | AE15: 4GB | AF15: 250GB | AG15: WINDOWS 11 PRO | AH15: 44351 | AI15: 44787 | AJ15: =FLOOR(YEARFRAC(AH15, TODAY(), 1),1) -> 4 | AL15: JHONATHAN ARMANDO CAMARGO IZQUIERDO | AN15: N/A | AO15: N/A | AP15: N/A | AQ15: N/A | AR15: {=IFERROR(XLOOKUP(V15,'AV 23-12-2025'!A:A,'AV 23-12-2025'!D:D),"zz.No cruza con AV")} -> zz.No cruza con AV | AS15: {=IFERROR(XLOOKUP(V15,'AV 23-12-2025'!A:A,'AV 23-12-2025'!C:C), "No cruza con AV")} -> No cruza con AV | AT15: No cruza con Antivirus
A16: FEDERACIÓN | B16: SUCURSAL IBAGUE | C16: FON1 | D16: FEDERACIÓN | E16: EMPLEADO | F16: 65719793 | G16: 65719793 | H16: BELLY LUZ DELGADO ARBOLEDA | I16: TOLIMA | J16: IBAGUE | K16: COORDINADOR SECCIONAL EXTENSION RURAL | L16: SECCIONAL RIOBLANCO | M16: 2 | N16: RECURSO PROPIO | O16: N/A | P16: N/A | Q16: N/A | R16: N/A | S16: N/A | U16: EQUIPO PORTATIL | V16: FVVJS93 | W16: 10105232 | X16: DELL | Y16: Latitude 3420 | Z16: L11FETOLRENOV2 | AA16: EN OPERACION | AB16: ASIGNACION RESPONSABLE | AC16: CONTROLADO | AD16: I3-1115g4 | AE16: 4GB | AF16: 250GB | AG16: WINDOWS 11 PRO | AH16: 44351 | AI16: 44787 | AJ16: =FLOOR(YEARFRAC(AH16, TODAY(), 1),1) -> 4 | AL16: JHONATHAN ARMANDO CAMARGO IZQUIERDO | AN16: N/A | AO16: N/A | AP16: N/A | AQ16: N/A | AR16: {=IFERROR(XLOOKUP(V16,'AV 23-12-2025'!A:A,'AV 23-12-2025'!D:D),"zz.No cruza con AV")} -> zz.No cruza con AV | AS16: {=IFERROR(XLOOKUP(V16,'AV 23-12-2025'!A:A,'AV 23-12-2025'!C:C), "No cruza con AV")} -> No cruza con AV | AT16: No cruza con Antivirus
A17: FEDERACIÓN | B17: SUCURSAL IBAGUE | C17: FON1 | D17: FEDERACIÓN | E17: EMPLEADO | F17: 1058274307 | H17: CARLOS ALFONSO TIBADUIZA VIANCHA | I17: TOLIMA | J17: IBAGUE | K17: COORDINADOR PROGRAMA | L17: PROGRAMA BENEFICIO Y CALIDAD | M17: 2 | N17: RECURSO PROPIO | O17: N/A | P17: N/A | Q17: N/A | R17: N/A | S17: N/A | U17: EQUIPO ESCRITORIO | V17: 207FMJ3 | W17: 10095983 | X17: DELL | Y17: OPTIPLEX 3080 | Z17: D10FETOLCTIB01 | AA17: EN OPERACION | AB17: ASIGNACION RESPONSABLE | AC17: CONTROLADO | AD17: I5-10500t | AE17: 16GB | AF17: 500GB | AG17: WINDOWS 10 PRO | AH17: 44525 | AI17: 45690 | AJ17: =FLOOR(YEARFRAC(AH17, TODAY(), 1),1) -> 4 | AL17: JHONATHAN ARMANDO CAMARGO IZQUIERDO | AN17: N/A | AO17: PERFIL 3 | AP17: DESKTOP TOWER/SFF DE ALTO RENDIMIENTO | AQ17: RECURSOS BOGOTA | AR17: {=IFERROR(XLOOKUP(V17,'AV 23-12-2025'!A:A,'AV 23-12-2025'!D:D),"zz.No cruza con AV")} -> 19/12/25 17:53:03 COT | AS17: {=IFERROR(XLOOKUP(V17,'AV 23-12-2025'!A:A,'AV 23-12-2025'!C:C), "No cruza con AV")} -> Carlos Tibaduiza | AT17: Si cruza con Antivirus
A18: FEDERACIÓN | B18: SUCURSAL IBAGUE | C18: FON1 | D18: FEDERACIÓN | E18: CONTRATISTA | F18: 1110552207 | G18: CGUERRA207 | H18: CRISTHIAN FELIPE GUERRA RODRIGUEZ | I18: TOLIMA | J18: IBAGUE | K18: AUXILIAR ADMINISTRATIVO | L18: BENEFICIO ECOLOGICO | M18: 2 | N18: RECURSO PROPIO | O18: 1110585547 | P18: GERMAN CAMILO ROMERO MOSQUERA | Q18: COORDINADOR BENEFICIO ECOLOGICO | R18: IBAGUE | S18: BENEFICIO ECOLOGICO | T18: RECURSO PROPIO | U18: EQUIPO PORTATIL | V18: 35WJS93 | W18: 10105229 | X18: DELL | Y18: Latitude 3420 | Z18: L11FETOLREN4 | AA18: EN OPERACION | AB18: ASIGNACION RESPONSABLE | AC18: CONTROLADO | AD18: I3-1115g4 | AE18: 4GB | AF18: 250GB | AG18: WINDOWS 11 PRO | AH18: 44351 | AI18: 44787 | AJ18: =FLOOR(YEARFRAC(AH18, TODAY(), 1),1) -> 4 | AL18: JHONATHAN ARMANDO CAMARGO IZQUIERDO | AN18: N/A | AO18: N/A | AP18: N/A | AQ18: N/A | AR18: {=IFERROR(XLOOKUP(V18,'AV 23-12-2025'!A:A,'AV 23-12-2025'!D:D),"zz.No cruza con AV")} -> 23/12/25 12:39:31 COT | AS18: {=IFERROR(XLOOKUP(V18,'AV 23-12-2025'!A:A,'AV 23-12-2025'!C:C), "No cruza con AV")} -> Renova4 | AT18: Si cruza con Antivirus
A19: FEDERACIÓN | B19: SUCURSAL IBAGUE | C19: FON1 | D19: FEDERACIÓN | E19: EMPLEADO | F19: 93387546 | G19: FEFEPER | H19: FERNANDO PEREZ MARTINEZ | I19: TOLIMA | J19: IBAGUE | K19: PROFESIONAL DESARROLLO SOCIAL | L19: DESARROLLO SOCIAL | M19: 2 | N19: RECURSO PROPIO | O19: N/A | P19: N/A | Q19: N/A | R19: N/A | S19: N/A | U19: EQUIPO PORTATIL | V19: 1ZDSGJ3 | W19: 10095969 | X19: DELL | Y19: Vostro 3400 | Z19: L10FETOLFPER | AA19: EN OPERACION | AB19: ASIGNACION RESPONSABLE | AC19: CONTROLADO | AD19: I5-1135g7 | AE19: 16GB | AF19: 500GB | AG19: WINDOWS 11 PRO | AH19: 44512 | AI19: 44947 | AJ19: =FLOOR(YEARFRAC(AH19, TODAY(), 1),1) -> 4 | AL19: JHONATHAN ARMANDO CAMARGO IZQUIERDO | AN19: N/A | AO19: N/A | AP19: N/A | AQ19: N/A | AR19: {=IFERROR(XLOOKUP(V19,'AV 23-12-2025'!A:A,'AV 23-12-2025'!D:D),"zz.No cruza con AV")} -> 23/12/25 12:01:10 COT | AS19: {=IFERROR(XLOOKUP(V19,'AV 23-12-2025'!A:A,'AV 23-12-2025'!C:C), "No cruza con AV")} -> DELL | AT19: Si cruza con Antivirus
A20: FEDERACIÓN | B20: SUCURSAL IBAGUE | C20: FON1 | D20: FEDERACIÓN | E20: EMPLEADO | F20: 93410091 | G20: HHINCAP091 | H20: HECTOR JAVIER HINCAPIE ARISTIZABAL | I20: TOLIMA | J20: IBAGUE | K20: COORDINADOR PROGRAMA | L20: PROGRAMA SICA | M20: 2 | N20: RECURSO PROPIO | O20: N/A | P20: N/A | Q20: N/A | R20: N/A | S20: N/A | U20: EQUIPO ESCRITORIO | V20: 507FMJ3 | W20: 1009582 | X20: DELL | Y20: OPTIPLEX 3080 | Z20: PENDIENTE SIN ROOT | AA20: EN OPERACION | AB20: ASIGNACION RESPONSABLE | AC20: CONTROLADO | AD20: I5-10500t | AE20: 8GB | AF20: 250GB | AG20: WINDOWS 11 PRO | AH20: 44525 | AI20: 45690 | AJ20: =FLOOR(YEARFRAC(AH20, TODAY(), 1),1) -> 4 | AL20: JHONATHAN ARMANDO CAMARGO IZQUIERDO | AN20: N/A | AO20: PERFIL 3 | AP20: DESKTOP TOWER/SFF DE ALTO RENDIMIENTO | AQ20: RECURSOS BOGOTA | AR20: {=IFERROR(XLOOKUP(V20,'AV 23-12-2025'!A:A,'AV 23-12-2025'!D:D),"zz.No cruza con AV")} -> 19/12/25 12:16:18 COT | AS20: {=IFERROR(XLOOKUP(V20,'AV 23-12-2025'!A:A,'AV 23-12-2025'!C:C), "No cruza con AV")} -> Javier Hincapie | AT20: Si cruza con Antivirus
A21: FEDERACIÓN | B21: SUCURSAL IBAGUE | C21: FON1 | D21: FEDERACIÓN | E21: EMPLEADO | F21: 38210802 | G21: YBONILL802 | H21: YENNY PAOLA BONILLA ROJAS | I21: TOLIMA | J21: IBAGUE | K21: COORDINADOR ADMINISTRATIVO | L21: ADMINISTRATIVOS | M21: 2 | N21: RECURSO PROPIO | O21: N/A | P21: N/A | Q21: N/A | R21: N/A | S21: N/A | U21: EQUIPO PORTATIL | V21: G4K54B3 | W21: 10095920 | X21: DELL | Y21: Latitude | Z21: L10FETOLAROM | AA21: EN OPERACION | AB21: ASIGNACION RESPONSABLE | AC21: CONTROLADO | AD21: I3-115g4 | AE21: 8GB | AF21: 250GB | AG21: WINDOWS 11 PRO | AH21: 44412 | AI21: 45540 | AJ21: =FLOOR(YEARFRAC(AH21, TODAY(), 1),1) -> 4 | AL21: JHONATHAN ARMANDO CAMARGO IZQUIERDO | AN21: N/A | AO21: N/A | AP21: N/A | AQ21: N/A | AR21: {=IFERROR(XLOOKUP(V21,'AV 23-12-2025'!A:A,'AV 23-12-2025'!D:D),"zz.No cruza con AV")} -> 22/12/25 13:29:04 COT | AS21: {=IFERROR(XLOOKUP(V21,'AV 23-12-2025'!A:A,'AV 23-12-2025'!C:C), "No cruza con AV")} -> Alejandra Romero | AT21: Si cruza con Antivirus
A22: FEDERACIÓN | B22: SUCURSAL IBAGUE | C22: FON1 | D22: FEDERACIÓN | E22: EMPLEADO | F22: 1104939227 | H22: MARIA JOSE AYA VARELA | I22: TOLIMA | J22: IBAGUE | K22: AUXILIAR ADMINISTRATIVO | L22: ADMINISTRATIVOS | M22: 2 | N22: RECURSO PROPIO | O22: N/A | P22: N/A | Q22: N/A | R22: N/A | S22: N/A | U22: EQUIPO ESCRITORIO | V22: D1DNH03 | W22: 10085705 | X22: DELL | Y22: OPTIPLEX 3070 | Z22: D11FETOLMAYA01 | AA22: EN OPERACION | AB22: ASIGNACION RESPONSABLE | AC22: CONTROLADO | AD22: I5-9500 | AE22: 16GB | AF22: 500GB | AG22: WINDOWS 11 PRO | AH22: 43805 | AI22: 44931 | AJ22: =FLOOR(YEARFRAC(AH22, TODAY(), 1),1) -> 6 | AL22: JHONATHAN ARMANDO CAMARGO IZQUIERDO | AN22: N/A | AO22: N/A | AP22: N/A | AQ22: N/A | AR22: {=IFERROR(XLOOKUP(V22,'AV 23-12-2025'!A:A,'AV 23-12-2025'!D:D),"zz.No cruza con AV")} -> 23/12/25 12:44:17 COT | AS22: {=IFERROR(XLOOKUP(V22,'AV 23-12-2025'!A:A,'AV 23-12-2025'!C:C), "No cruza con AV")} -> Valentina Vergara | AT22: Si cruza con Antivirus
A23: FEDERACIÓN | B23: SUCURSAL IBAGUE | C23: FON1 | D23: FEDERACIÓN | E23: EMPLEADO | F23: 38210802 | G23: YBONILL802 | H23: YENNY PAOLA BONILLA ROJAS | I23: TOLIMA | J23: IBAGUE | K23: COORDINADOR ADMINISTRATIVO | L23: ADMINISTRATIVOS | M23: 2 | N23: RECURSO PROPIO | O23: N/A | P23: N/A | Q23: N/A | R23: N/A | S23: N/A | U23: EQUIPO PORTATIL | V23: 5CG03799TD | W23: 10085754 | X23: HP | Y23: Hp 240 g7 | Z23: L10FETOLYBON2 | AA23: EN OPERACION | AB23: ASIGNACION RESPONSABLE | AC23: CONTROLADO | AD23: I5-1035g1 | AE23: 8GB | AF23: 250GB | AG23: WINDOWS 11 PRO | AH23: 44138 | AI23: 44502 | AJ23: =FLOOR(YEARFRAC(AH23, TODAY(), 1),1) -> 5 | AL23: JHONATHAN ARMANDO CAMARGO IZQUIERDO | AN23: N/A | AO23: N/A | AP23: N/A | AQ23: N/A | AR23: {=IFERROR(XLOOKUP(V23,'AV 23-12-2025'!A:A,'AV 23-12-2025'!D:D),"zz.No cruza con AV")} -> zz.No cruza con AV | AS23: {=IFERROR(XLOOKUP(V23,'AV 23-12-2025'!A:A,'AV 23-12-2025'!C:C), "No cruza con AV")} -> No cruza con AV | AT23: No cruza con Antivirus
A24: FEDERACIÓN | B24: SUCURSAL IBAGUE | C24: FON1 | D24: FEDERACIÓN | E24: EMPLEADO | F24: 28554485 | G24: FTEROJ | H24: EDNA MAGALLY ROJAS HERRERA | I24: TOLIMA | J24: IBAGUE | K24: COORDINADOR FINANCIERO | L24: FINANCIEROS | M24: 2 | N24: RECURSO PROPIO | O24: N/A | P24: N/A | Q24: N/A | R24: N/A | S24: N/A | U24: EQUIPO ESCRITORIO | V24: 4QVWHV2 | W24: 10081783 | X24: DELL | Y24: OPTIPLEX 3060 | Z24: W10FETOLEROJ | AA24: EN OPERACION | AB24: ASIGNACION RESPONSABLE | AC24: CONTROLADO | AD24: I5-8400 | AE24: 16GB | AF24: 500GB | AG24: WINDOWS 11 PRO | AH24: 43546 | AI24: 44672 | AJ24: =FLOOR(YEARFRAC(AH24, TODAY(), 1),1) -> 6 | AL24: JHONATHAN ARMANDO CAMARGO IZQUIERDO | AN24: N/A | AO24: N/A | AP24: N/A | AQ24: N/A | AR24: {=IFERROR(XLOOKUP(V24,'AV 23-12-2025'!A:A,'AV 23-12-2025'!D:D),"zz.No cruza con AV")} -> 23/12/25 12:46:03 COT | AS24: {=IFERROR(XLOOKUP(V24,'AV 23-12-2025'!A:A,'AV 23-12-2025'!C:C), "No cruza con AV")} -> Magally Rojas | AT24: Si cruza con Antivirus
A25: FEDERACIÓN | B25: SUCURSAL IBAGUE | C25: FON1 | D25: FEDERACIÓN | E25: EMPLEADO | F25: 1110584632 | G25: EDUQUE632 | H25: EDUARD DAVID DUQUE OTALVARO | I25: TOLIMA | J25: IBAGUE | K25: ANALISTA FINANCIERO | L25: FINANCIEROS | M25: 2 | N25: RECURSO PROPIO | O25: N/A | P25: N/A | Q25: N/A | R25: N/A | S25: N/A | U25: EQUIPO ESCRITORIO | V25: 9479778446 | W25: 10081782 | X25: DELL | Y25: OPTIPLEX 360 | Z25: D10FETOLEDUQ01 | AA25: EN OPERACION | AB25: ASIGNACION RESPONSABLE | AC25: CONTROLADO | AD25: I5-8400 | AE25: 8GB | AF25: 500GB | AG25: WINDOWS 10 PRO | AH25: 43546 | AI25: 44672 | AJ25: =FLOOR(YEARFRAC(AH25, TODAY(), 1),1) -> 6 | AL25: JHONATHAN ARMANDO CAMARGO IZQUIERDO | AN25: N/A | AO25: PERFIL 1 | AP25: DESKTOP | AQ25: PAC | AR25: {=IFERROR(XLOOKUP(V25,'AV 23-12-2025'!A:A,'AV 23-12-2025'!D:D),"zz.No cruza con AV")} -> zz.No cruza con AV | AS25: {=IFERROR(XLOOKUP(V25,'AV 23-12-2025'!A:A,'AV 23-12-2025'!C:C), "No cruza con AV")} -> No cruza con AV | AT25: No cruza con Antivirus
A26: FEDERACIÓN | B26: SUCURSAL IBAGUE | C26: FON1 | D26: FEDERACIÓN | E26: EMPLEADO | F26: 65748443 | G26: FEMHER | H26: MARIA VICTORIA HERRERA POLANIA | I26: TOLIMA | J26: IBAGUE | K26: COORDINADOR PROGRAMA | L26: PROGRAMA COMUNICACIONES | M26: 2 | N26: RECURSO PROPIO | O26: N/A | P26: N/A | Q26: N/A | R26: N/A | S26: N/A | U26: EQUIPO ESCRITORIO | V26: 7NP4FW2 | W26: 10085607 | X26: DELL | Y26: OPTIPLEX 3060 | Z26: W11FETOLMVHERRE | AA26: EN OPERACION | AB26: ASIGNACION RESPONSABLE | AC26: CONTROLADO | AD26: I5-8400 | AE26: 16GB | AF26: 250GB | AG26: WINDOWS 11 PRO | AH26: 43609 | AI26: 44892 | AJ26: =FLOOR(YEARFRAC(AH26, TODAY(), 1),1) -> 6 | AL26: JHONATHAN ARMANDO CAMARGO IZQUIERDO | AN26: N/A | AO26: PERFIL 3 | AP26: DESKTOP TOWER/SFF DE ALTO RENDIMIENTO | AQ26: RECURSOS BOGOTA | AR26: {=IFERROR(XLOOKUP(V26,'AV 23-12-2025'!A:A,'AV 23-12-2025'!D:D),"zz.No cruza con AV")} -> 19/12/25 17:39:58 COT | AS26: {=IFERROR(XLOOKUP(V26,'AV 23-12-2025'!A:A,'AV 23-12-2025'!C:C), "No cruza con AV")} -> Maria Herrera | AT26: Si cruza con Antivirus
A27: FEDERACIÓN | B27: SUCURSAL IBAGUE | C27: FON1 | D27: FEDERACIÓN | E27: EMPLEADO | F27: 1005720239 | G27: SCANO239 | H27: SARA VALENTINA CANO OSPINA | I27: TOLIMA | J27: IBAGUE | K27: AUXILIAR ADMINISTRATIVO | L27: ADMINISTRATIVOS | M27: 2 | N27: RECURSO PROPIO | O27: N/A | P27: N/A | Q27: N/A | R27: N/A | S27: N/A | U27: EQUIPO ESCRITORIO | V27: 4QRZHV2 | W27: 10081781 | X27: DELL | Y27: OPTIPLEX 3060 | Z27: D10FETOLSCAN01 | AA27: EN OPERACION | AB27: ASIGNACION RESPONSABLE | AC27: CONTROLADO | AD27: I5-8400 | AE27: 8GB | AF27: 500GB | AG27: WINDOWS 11 PRO | AH27: 43546 | AI27: 44672 | AJ27: =FLOOR(YEARFRAC(AH27, TODAY(), 1),1) -> 6 | AL27: JHONATHAN ARMANDO CAMARGO IZQUIERDO | AN27: N/A | AO27: N/A | AP27: N/A | AQ27: N/A | AR27: {=IFERROR(XLOOKUP(V27,'AV 23-12-2025'!A:A,'AV 23-12-2025'!D:D),"zz.No cruza con AV")} -> 23/12/25 10:58:55 COT | AS27: {=IFERROR(XLOOKUP(V27,'AV 23-12-2025'!A:A,'AV 23-12-2025'!C:C), "No cruza con AV")} -> Sara Cano | AT27: Si cruza con Antivirus
A28: FEDERACIÓN | B28: SUCURSAL IBAGUE | C28: FON1 | D28: FEDERACIÓN | E28: EMPLEADO | F28: 93362708 | G28: CO93362708 | H28: FERNANDO AUGUSTO VARGAS RIOS | I28: TOLIMA | J28: IBAGUE | K28: ANALISTA | L28: EXTENSION RURAL | M28: 2 | N28: RECURSO PROPIO | O28: N/A | P28: N/A | Q28: N/A | R28: N/A | S28: N/A | U28: EQUIPO ESCRITORIO | V28: 6XL41M2 | W28: 20008744 | X28: DELL | Y28: OPTIPLEX 3050 | Z28: D10FETOLFVAR01 | AA28: EN OPERACION | AB28: ASIGNACION RESPONSABLE | AC28: CONTROLADO | AD28: I5-7500 | AE28: 8GB | AF28: 500GB | AG28: WINDOWS 10 PRO | AH28: 43073 | AI28: 44199 | AJ28: =FLOOR(YEARFRAC(AH28, TODAY(), 1),1) -> 8 | AL28: JHONATHAN ARMANDO CAMARGO IZQUIERDO | AN28: N/A | AO28: PERFIL 1 | AP28: DESKTOP | AQ28: PAC | AR28: {=IFERROR(XLOOKUP(V28,'AV 23-12-2025'!A:A,'AV 23-12-2025'!D:D),"zz.No cruza con AV")} -> 23/12/25 12:22:25 COT | AS28: {=IFERROR(XLOOKUP(V28,'AV 23-12-2025'!A:A,'AV 23-12-2025'!C:C), "No cruza con AV")} -> Fernando Vargas | AT28: Si cruza con Antivirus
A29: FEDERACIÓN | B29: SUCURSAL IBAGUE | C29: FON1 | D29: FEDERACIÓN | E29: EMPLEADO | F29: 65553626 | G29: IRAMIRE626 | H29: ILSA RAMIREZ RAMIREZ | I29: TOLIMA | J29: IBAGUE | K29: ANALISTA FINANCIERO | L29: FINANCIEROS | M29: 2 | N29: RECURSO PROPIO | O29: N/A | P29: N/A | Q29: N/A | R29: N/A | S29: N/A | U29: EQUIPO ESCRITORIO | V29: 74VZ0M2 | W29: 20008877 | X29: DELL | Y29: OPTIPLEX 3050 | Z29: W11FETOLIRAM | AA29: EN OPERACION | AB29: ASIGNACION RESPONSABLE | AC29: CONTROLADO | AD29: I5-7500 | AE29: 8GB | AF29: 500GB | AG29: WINDOWS 11 PRO | AH29: 43073 | AI29: 44199 | AJ29: =FLOOR(YEARFRAC(AH29, TODAY(), 1),1) -> 8 | AL29: JHONATHAN ARMANDO CAMARGO IZQUIERDO | AN29: N/A | AO29: N/A | AP29: N/A | AQ29: N/A | AR29: {=IFERROR(XLOOKUP(V29,'AV 23-12-2025'!A:A,'AV 23-12-2025'!D:D),"zz.No cruza con AV")} -> zz.No cruza con AV | AS29: {=IFERROR(XLOOKUP(V29,'AV 23-12-2025'!A:A,'AV 23-12-2025'!C:C), "No cruza con AV")} -> No cruza con AV | AT29: No cruza con Antivirus
A30: FEDERACIÓN | B30: SUCURSAL IBAGUE | C30: FON1 | D30: FEDERACIÓN | E30: EMPLEADO | F30: 39580689 | G30: FEBMAR | H30: BIBIANA MARCELA MARTINEZ BARRERO | I30: TOLIMA | J30: IBAGUE | K30: AUXILIAR ADMINISTRATIVO | L30: ADMINISTRATIVOS | M30: 2 | N30: RECURSO PROPIO | O30: N/A | P30: N/A | Q30: N/A | R30: N/A | S30: N/A | U30: EQUIPO ESCRITORIO | V30: 1FYTSD2 | W30: 10078204 | X30: DELL | Y30: OPTIPLEX 3040 | Z30: W11FETOLBIMA | AA30: EN OPERACION | AB30: ASIGNACION RESPONSABLE | AC30: CONTROLADO | AD30: I5-6500 | AE30: 8GB | AF30: 500GB | AG30: WINDOWS 11 PRO | AH30: 42697 | AI30: 43823 | AJ30: =FLOOR(YEARFRAC(AH30, TODAY(), 1),1) -> 9 | AL30: JHONATHAN ARMANDO CAMARGO IZQUIERDO | AN30: N/A | AO30: N/A | AP30: N/A | AQ30: N/A | AR30: {=IFERROR(XLOOKUP(V30,'AV 23-12-2025'!A:A,'AV 23-12-2025'!D:D),"zz.No cruza con AV")} -> 23/12/25 12:55:16 COT | AS30: {=IFERROR(XLOOKUP(V30,'AV 23-12-2025'!A:A,'AV 23-12-2025'!C:C), "No cruza con AV")} -> Bibiana Martinez | AT30: Si cruza con Antivirus
A31: FEDERACIÓN | B31: SUCURSAL IBAGUE | C31: FON1 | D31: FEDERACIÓN | E31: EMPLEADO | F31: 28548604 | G31: FELPLOP | H31: LINA PASTORA LOPERA MORENO | I31: TOLIMA | J31: IBAGUE | K31: ANALISTA | L31: PROGRAMA SICA | M31: 2 | N31: RECURSO PROPIO | O31: N/A | P31: N/A | Q31: N/A | R31: N/A | S31: N/A | U31: EQUIPO ESCRITORIO | V31: 1FYMSD2 | W31: 10078203 | X31: DELL | Y31: OPTIPLEX 3040 | Z31: W11FETOLLLOP | AA31: EN OPERACION | AB31: ASIGNACION RESPONSABLE | AC31: CONTROLADO | AD31: I5-6500 | AE31: 8GB | AF31: 250GB | AG31: WINDOWS 11 PRO | AH31: 42697 | AI31: 43793 | AJ31: =FLOOR(YEARFRAC(AH31, TODAY(), 1),1) -> 9 | AL31: JHONATHAN ARMANDO CAMARGO IZQUIERDO | AN31: N/A | AO31: N/A | AP31: N/A | AQ31: N/A | AR31: {=IFERROR(XLOOKUP(V31,'AV 23-12-2025'!A:A,'AV 23-12-2025'!D:D),"zz.No cruza con AV")} -> 19/12/25 15:54:57 COT | AS31: {=IFERROR(XLOOKUP(V31,'AV 23-12-2025'!A:A,'AV 23-12-2025'!C:C), "No cruza con AV")} -> Lina Lopera | AT31: Si cruza con Antivirus
A32: FEDERACIÓN | B32: SUCURSAL IBAGUE | C32: FON1 | D32: FEDERACIÓN | E32: EMPLEADO | F32: 1110541614 | H32: JHONATHAN ARMANDO CAMARGO IZQUIERDO | I32: TOLIMA | J32: IBAGUE | K32: ANALISTA TIC | L32: TIC | M32: 2 | N32: RECURSO PROPIO | O32: N/A | P32: N/A | Q32: N/A | R32: N/A | S32: N/A | U32: EQUIPO PORTATIL | V32: C2YF5C2 | W32: 10070724 | X32: DELL | Y32: LATITUD 3560 | Z32: No Aplica | AA32: ALMACENADO | AB32: RETORNO | AC32: CONTROLADO | AD32: i5-5200U | AE32: 8GB | AF32: No Aplica | AG32: No Aplica | AH32: 42696 | AI32: 43822 | AJ32: =FLOOR(YEARFRAC(AH32, TODAY(), 1),1) -> 9 | AL32: JHONATHAN ARMANDO CAMARGO IZQUIERDO | AN32: OBSOLETO | AO32: N/A | AP32: N/A | AQ32: N/A | AR32: {=IFERROR(XLOOKUP(V32,'AV 23-12-2025'!A:A,'AV 23-12-2025'!D:D),"zz.No cruza con AV")} -> 9/10/25 9:52:04 COT | AS32: {=IFERROR(XLOOKUP(V32,'AV 23-12-2025'!A:A,'AV 23-12-2025'!C:C), "No cruza con AV")} -> MariaP Patiño | AT32: Si cruza con Antivirus
A33: FEDERACIÓN | B33: SUCURSAL IBAGUE | C33: FON1 | D33: FEDERACIÓN | E33: EMPLEADO | F33: 1110541614 | H33: JHONATHAN ARMANDO CAMARGO IZQUIERDO | I33: TOLIMA | J33: IBAGUE | K33: ANALISTA TIC | L33: TIC | M33: 2 | N33: RECURSO PROPIO | O33: N/A | P33: N/A | Q33: N/A | R33: N/A | S33: N/A | U33: EQUIPO TODO EN UNO | V33: P9017H90 | X33: LENOVO | Y33: IDEA CENTRE AiO 700-24ISH | Z33: No Aplica | AA33: ALMACENADO | AB33: ALISTAMIENTO/SOPORTE | AC33: CONTROLADO | AD33: Core i7 6700 | AE33: 12GB | AF33: No Aplica | AG33: No Aplica | AH33: 42430 | AI33: 42491 | AJ33: =FLOOR(YEARFRAC(AH33, TODAY(), 1),1) -> 9 | AL33: JHONATHAN ARMANDO CAMARGO IZQUIERDO | AN33: FALLA EN PANTALLA - SIN SO | AO33: N/A | AP33: N/A | AQ33: N/A | AR33: {=IFERROR(XLOOKUP(V33,'AV 23-12-2025'!A:A,'AV 23-12-2025'!D:D),"zz.No cruza con AV")} -> zz.No cruza con AV | AS33: {=IFERROR(XLOOKUP(V33,'AV 23-12-2025'!A:A,'AV 23-12-2025'!C:C), "No cruza con AV")} -> No cruza con AV | AT33: No cruza con Antivirus
A34: FEDERACIÓN | B34: SUCURSAL IBAGUE | C34: FON1 | D34: FEDERACIÓN | E34: EMPLEADO | F34: 1005701133 | G34: GECHEVE133 | H34: GABRIELA ECHEVERRY ESCOBAR | I34: TOLIMA | J34: IBAGUE | K34: ANALISTA COMPRAS | L34: BIENES Y SERVICIOS | M34: 2 | N34: RECURSO PROPIO | O34: N/A | P34: N/A | Q34: N/A | R34: N/A | S34: N/A | U34: EQUIPO ESCRITORIO | V34: G2P7S22 | W34: 10065509 | X34: DELL | Y34: OPTIPLEX 9020 | Z34: D10FETOLGECH01 | AA34: EN OPERACION | AB34: ASIGNACION RESPONSABLE | AC34: CONTROLADO | AD34: I5-4590 | AE34: 12GB | AF34: 500GB | AG34: WINDOWS 10 PRO | AH34: 42012 | AI34: 43139 | AJ34: =FLOOR(YEARFRAC(AH34, TODAY(), 1),1) -> 11 | AL34: JHONATHAN ARMANDO CAMARGO IZQUIERDO | AN34: N/A | AO34: PERFIL 2 | AP34: LAPTOP | AQ34: RECURSOS PROPIOS | AR34: {=IFERROR(XLOOKUP(V34,'AV 23-12-2025'!A:A,'AV 23-12-2025'!D:D),"zz.No cruza con AV")} -> 22/12/25 16:22:44 COT | AS34: {=IFERROR(XLOOKUP(V34,'AV 23-12-2025'!A:A,'AV 23-12-2025'!C:C), "No cruza con AV")} -> Gabriela Echeverry | AT34: Si cruza con Antivirus
A35: FEDERACIÓN | B35: SUCURSAL IBAGUE | C35: FON1 | D35: FEDERACIÓN | E35: EMPLEADO | F35: 1109419709 | H35: KELLY MARCELA GARZON ESPINOSA | I35: TOLIMA | J35: IBAGUE | K35: AUXILIAR ADMINISTRATIVO | L35: ADMINISTRATIVOS | M35: 2 | N35: RECURSO PROPIO | O35: N/A | P35: N/A | Q35: N/A | R35: N/A | S35: N/A | U35: EQUIPO ESCRITORIO | V35: G2MXR22 | W35: 10065508 | X35: DELL | Y35: OPTIPLEX 9020 | Z35: D10FETOLKGAR01 | AA35: EN OPERACION | AB35: ASIGNACION RESPONSABLE | AC35: CONTROLADO | AD35: I5-4590 | AE35: 16GB | AF35: 250GB | AG35: WINDOWS 10 PRO | AH35: 42012 | AI35: 43139 | AJ35: =FLOOR(YEARFRAC(AH35, TODAY(), 1),1) -> 11 | AL35: JHONATHAN ARMANDO CAMARGO IZQUIERDO | AN35: N/A | AO35: PERFIL 1 | AP35: DESKTOP | AQ35: PAC | AR35: {=IFERROR(XLOOKUP(V35,'AV 23-12-2025'!A:A,'AV 23-12-2025'!D:D),"zz.No cruza con AV")} -> 23/12/25 12:14:14 COT | AS35: {=IFERROR(XLOOKUP(V35,'AV 23-12-2025'!A:A,'AV 23-12-2025'!C:C), "No cruza con AV")} -> KELLY GARZON | AT35: Si cruza con Antivirus
A36: FEDERACIÓN | B36: SUCURSAL IBAGUE | C36: FON1 | D36: FEDERACIÓN | E36: EMPLEADO | F36: 1110541614 | H36: JHONATHAN ARMANDO CAMARGO IZQUIERDO | I36: TOLIMA | J36: IBAGUE | K36: ANALISTA TIC | L36: TIC | M36: 2 | N36: RECURSO PROPIO | O36: N/A | P36: N/A | Q36: N/A | R36: N/A | S36: N/A | U36: EQUIPO PORTATIL | V36: 96TKL32 | W36: 10065498 | X36: DELL | Y36: LATITUDE E5440 | Z36: No Aplica | AA36: ALMACENADO | AB36: ALISTAMIENTO/SOPORTE | AC36: CONTROLADO | AD36: Core i5-3230M | AE36: N/A | AF36: No Aplica | AG36: No Aplica | AH36: 42074 | AI36: 43200 | AJ36: =FLOOR(YEARFRAC(AH36, TODAY(), 1),1) -> 10 | AL36: JHONATHAN ARMANDO CAMARGO IZQUIERDO | AN36: SIN HDD - SIN RAM - CORTO BOARD | AO36: N/A | AP36: N/A | AQ36: N/A | AR36: {=IFERROR(XLOOKUP(V36,'AV 23-12-2025'!A:A,'AV 23-12-2025'!D:D),"zz.No cruza con AV")} -> zz.No cruza con AV | AS36: {=IFERROR(XLOOKUP(V36,'AV 23-12-2025'!A:A,'AV 23-12-2025'!C:C), "No cruza con AV")} -> No cruza con AV | AT36: No cruza con Antivirus
A37: FEDERACIÓN | B37: SUCURSAL IBAGUE | C37: FON1 | D37: FEDERACIÓN | E37: EMPLEADO | F37: 1110541614 | H37: JHONATHAN ARMANDO CAMARGO IZQUIERDO | I37: TOLIMA | J37: IBAGUE | K37: ANALISTA TIC | L37: TIC | M37: 2 | N37: RECURSO PROPIO | O37: N/A | P37: N/A | Q37: N/A | R37: N/A | S37: N/A | U37: EQUIPO PORTATIL | V37: 92TKL32 | W37: 10065492 | X37: DELL | Y37: LATITUDE E5440 | Z37: No Aplica | AA37: ALMACENADO | AB37: ALISTAMIENTO/SOPORTE | AC37: CONTROLADO | AD37: Core i5-3230M | AE37: EXTRAIDA | AF37: No Aplica | AG37: No Aplica | AH37: 42074 | AI37: 43200 | AJ37: =FLOOR(YEARFRAC(AH37, TODAY(), 1),1) -> 10 | AL37: JHONATHAN ARMANDO CAMARGO IZQUIERDO | AN37: WIFI - USB - ETHERNET - PANTALLA | AO37: N/A | AP37: N/A | AQ37: N/A | AR37: {=IFERROR(XLOOKUP(V37,'AV 23-12-2025'!A:A,'AV 23-12-2025'!D:D),"zz.No cruza con AV")} -> zz.No cruza con AV | AS37: {=IFERROR(XLOOKUP(V37,'AV 23-12-2025'!A:A,'AV 23-12-2025'!C:C), "No cruza con AV")} -> No cruza con AV | AT37: No cruza con Antivirus
A38: FEDERACIÓN | B38: SUCURSAL IBAGUE | C38: FON1 | D38: FEDERACIÓN | E38: EMPLEADO | F38: 1110541614 | H38: JHONATHAN ARMANDO CAMARGO IZQUIERDO | I38: TOLIMA | J38: IBAGUE | K38: ANALISTA TIC | L38: TIC | M38: 2 | N38: RECURSO PROPIO | O38: N/A | P38: N/A | Q38: N/A | R38: N/A | S38: N/A | U38: EQUIPO PORTATIL | V38: 12TKL32 | W38: 10065493 | X38: DELL | Y38: LATITUDE E5440 | Z38: No Aplica | AA38: ALMACENADO | AB38: ALISTAMIENTO/SOPORTE | AC38: CONTROLADO | AD38: Core i5-4310U | AE38: 4GB | AF38: No Aplica | AG38: No Aplica | AH38: 42074 | AI38: 43200 | AJ38: =FLOOR(YEARFRAC(AH38, TODAY(), 1),1) -> 10 | AL38: JHONATHAN ARMANDO CAMARGO IZQUIERDO | AN38: BATERIA NO CARGA - SIN ADAPTADOR ENERGIA - NO ENCIENDE | AO38: N/A | AP38: N/A | AQ38: N/A | AR38: {=IFERROR(XLOOKUP(V38,'AV 23-12-2025'!A:A,'AV 23-12-2025'!D:D),"zz.No cruza con AV")} -> 9/10/25 15:29:43 COT | AS38: {=IFERROR(XLOOKUP(V38,'AV 23-12-2025'!A:A,'AV 23-12-2025'!C:C), "No cruza con AV")} -> Administrador | AT38: Si cruza con Antivirus
A39: FEDERACIÓN | B39: SUCURSAL IBAGUE | C39: FON1 | D39: FEDERACIÓN | E39: EMPLEADO | F39: 1110515041 | G39: JSANDOV041 | H39: JUAN CAMILO SANDOVAL GUZMAN | I39: TOLIMA | J39: IBAGUE | K39: ANALISTA BIENES Y SERVICIOS | L39: BIENES Y SERVICIOS | M39: 2 | N39: RECURSO PROPIO | O39: N/A | P39: N/A | Q39: N/A | R39: N/A | S39: N/A | U39: EQUIPO ESCRITORIO | V39: 21599474330 | W39: 10069362 | X39: DELL | Y39: OPTIPLEX 3020 | Z39: W10FETOLJSAND | AA39: EN OPERACION | AB39: ASIGNACION RESPONSABLE | AC39: CONTROLADO | AD39: I5-4590 | AE39: 12GB | AF39: 250GB | AG39: WINDOWS 10 PRO | AH39: 41947 | AI39: 43074 | AJ39: =FLOOR(YEARFRAC(AH39, TODAY(), 1),1) -> 11 | AL39: JHONATHAN ARMANDO CAMARGO IZQUIERDO | AN39: N/A | AO39: PERFIL 2 | AP39: LAPTOP | AQ39: RECURSOS PROPIOS | AR39: {=IFERROR(XLOOKUP(V39,'AV 23-12-2025'!A:A,'AV 23-12-2025'!D:D),"zz.No cruza con AV")} -> zz.No cruza con AV | AS39: {=IFERROR(XLOOKUP(V39,'AV 23-12-2025'!A:A,'AV 23-12-2025'!C:C), "No cruza con AV")} -> No cruza con AV | AT39: No cruza con Antivirus
A40: FEDERACIÓN | B40: SUCURSAL IBAGUE | C40: FON1 | D40: FEDERACIÓN | E40: EMPLEADO | F40: 65758694 | G40: FEMREY | H40: MARIA DEL CARMEN REYES BONILLA | I40: TOLIMA | J40: IBAGUE | K40: ANALISTA PLANEACION FINANCIERA Y PRESUPU | L40: PLANEACION FINANCIERA Y PRESUPUESTO | M40: 2 | N40: RECURSO PROPIO | O40: N/A | P40: N/A | Q40: N/A | R40: N/A | S40: N/A | U40: EQUIPO ESCRITORIO | V40: C6RVK02 | W40: 10069152 | X40: DELL | Y40: OPTIPLEX 7010 | Z40: W10FETOLMDCREY | AA40: EN OPERACION | AB40: ASIGNACION RESPONSABLE | AC40: CONTROLADO | AD40: i5-3570 | AE40: 4GB | AF40: 500GB | AG40: WINDOWS 10 PRO | AH40: 41743 | AI40: 42870 | AJ40: =FLOOR(YEARFRAC(AH40, TODAY(), 1),1) -> 11 | AL40: JHONATHAN ARMANDO CAMARGO IZQUIERDO | AN40: N/A | AO40: PERFIL 3 | AP40: DESKTOP TOWER/SFF DE ALTO RENDIMIENTO | AQ40: RECURSOS BOGOTA | AR40: {=IFERROR(XLOOKUP(V40,'AV 23-12-2025'!A:A,'AV 23-12-2025'!D:D),"zz.No cruza con AV")} -> 23/12/25 12:42:26 COT | AS40: {=IFERROR(XLOOKUP(V40,'AV 23-12-2025'!A:A,'AV 23-12-2025'!C:C), "No cruza con AV")} -> Maria Reyes | AT40: Si cruza con Antivirus
...

Sheet Tabla dinámica 2

Sheet AV 23-12-2025
A1: Número de serie del sistema | B1: Nombre de sistema | C1: Nombre de usuario | D1: Última comunicación | E1: Dirección IP | F1: Fabricante del sistema | G1: Sistema operativo | H1: Espacio total en disco | I1: Tipo de CPU | J1: Modelo del sistema | K1: Memoria física total | L1: ID de plataforma | M1: Plataforma de SO | N1: Nombre de grupo | O1: Versión de producto (Trellix DLP Endpoint) | P1: Dirección MAC | Q1: Clasificación del Árbol de sistemas
A2: 8CN30905BJ | B2: 022WXPFEQUIPA | C2: ALMACEN ARMENIA | D2: 23/12/25 12:54:42 COT | E2: 192.168.122.59 | F2: HP | G2: Tipo de SO:Windows 10,Plataforma de SO:Workstation,Versión de SO:10.0 | H2: 487207 MB | I2: 12th Gen Intel(R) Core(TM) i5-12500 | J2: HP ProOne 440 23.8 inch G9 All-in-One Desktop PC | K2: 16.053,58 MB | L2: Windows 10:10:0:0 | M2: Estación de trabajo | N2: Comite Quindio | O2: 11.11.2.1172 | P2: 7C4D8FF30953 | Q2: Desactivado
A3: 8CC1022Z6V | B3: 041WXPFEQUIPA | C3: ALMACEN CALARCA | D3: 23/12/25 11:58:06 COT | E3: 192.168.1.14 | F3: HP | G3: Tipo de SO:Windows 10,Plataforma de SO:Workstation,Versión de SO:10.0 | H3: 952018 MB | I3: Intel(R) Core(TM) i5-10210U CPU @ 1.60GHz | J3: HP 200 G4 22 All-in-One PC | K3: 8.016,82 MB | L3: Windows 10:10:0:0 | M3: Estación de trabajo | N3: Comite Quindio | O3: 11.11.2.1172 | P3: 6C02E07110F7 | Q3: Desactivado
A4: 8CTC8F3 | B4: 8CTC8F3-FNC-CUC | C4: CARMEN LUCIA VALLEJO | D4: 23/12/25 10:14:45 COT | E4: 192.168.1.7 | F4: Dell Inc. | G4: Tipo de SO:Windows 10,Plataforma de SO:Workstation,Versión de SO:10.0 | H4: 472477 MB | I4: 11th Gen Intel(R) Core(TM) i5-1135G7 @ 2.40GHz | J4: Inspiron 3501 | K4: 7.918,79 MB | L4: Windows 10:10:0:0 | M4: Estación de trabajo | N4: Comite Municipal Norte Santander | O4: 11.11.2.1172 | P4: C6DDC8150EB7 | Q4: Desactivado
A5: FL17XV3 | B5: ACORREDORG | C5: JMORENOCUN | D5: 23/12/25 12:55:53 COT | E5: ########## | F5: Dell Inc. | G5: Tipo de SO:Windows 11,Plataforma de SO:Workstation,Versión de SO:10.0 | H5: 485371 MB | I5: 13th Gen Intel(R) Core(TM) i5-13500T | J5: OptiPlex Micro 7010 | K5: 16.072,73 MB | L5: Windows 11:10:0:0 | M5: Estación de trabajo | N5: Comite Cundinamarca | O5: 11.11.2.1172 | P5: 7497797FC821 | Q5: Desactivado
A6: PF20P5RJ | B6: ADMI03 | C6: thoy | D6: 23/12/25 12:37:26 COT | E6: 192.168.40.67 | F6: LENOVO | G6: Tipo de SO:Windows 11,Plataforma de SO:Workstation,Versión de SO:10.0 | H6: 486878 MB | I6: Intel(R) Core(TM) i7-10510U CPU @ 1.80GHz | J6: 20UAS1TF00 | K6: 16.134,84 MB | L6: Windows 11:10:0:0 | M6: Estación de trabajo | N6: Buencafe_Fabrica | O6: 11.9.100.182 | P6: FCB3BC927FED | Q6: Desactivado
A7: PF3WLFF6 | B7: ADMI04 | C7: JGONZAL937 | D7: 23/12/25 12:39:43 COT | E7: 192.168.207.19 | F7: LENOVO | G7: Tipo de SO:Windows 11,Plataforma de SO:Workstation,Versión de SO:10.0 | H7: 486108 MB | I7: 11th Gen Intel(R) Core(TM) i7-1165G7 @ 2.80GHz | J7: 20TBS1PG00 | K7: 16.082,11 MB | L7: Windows 11:10:0:0 | M7: Estación de trabajo | N7: Buencafe_Fabrica | O7: 11.9.100.182 | P7: 88A4C2A218CD | Q7: Desactivado
A8: MP26TL4T | B8: ADMI05 | C8: SVALDER808,DTOBAR704 | D8: 23/12/25 12:43:03 COT | E8: 192.168.207.57 | F8: LENOVO | G8: Tipo de SO:Windows 11,Plataforma de SO:Workstation,Versión de SO:10.0 | H8: 487497 MB | I8: Intel(R) Core(TM) i7-10700T CPU @ 2.00GHz | J8: 11FJ00FWLS | K8: 16.195,00 MB | L8: Windows 11:10:0:0 | M8: Estación de trabajo | N8: Buencafe_Fabrica | O8: 11.9.100.182 | P8: E4A8DFA0BCC4 | Q8: Desactivado
A9: MJ0DNZ8P | B9: ADMI06 | C9: pgon | D9: 23/12/25 12:36:54 COT | E9: ########## | F9: LENOVO | G9: Tipo de SO:Windows 11,Plataforma de SO:Workstation,Versión de SO:10.0 | H9: 486991 MB | I9: Intel(R) Core(TM) i5-10600 CPU @ 3.30GHz | J9: 30DJS3A100 | K9: 16.091,41 MB | L9: Windows 11:10:0:0 | M9: Estación de trabajo | N9: Buencafe_Fabrica | O9: 11.9.100.182 | P9: 2CF05D51272D | Q9: Desactivado
A10: PF3WLLT5 | B10: ADMI07 | C10: LMZULUA473 | D10: 23/12/25 12:07:38 COT | E10: 192.168.40.94 | F10: LENOVO | G10: Tipo de SO:Windows 11,Plataforma de SO:Workstation,Versión de SO:10.0 | H10: 241920 MB | I10: 11th Gen Intel(R) Core(TM) i7-1165G7 @ 2.80GHz | J10: 20TBS10800 | K10: 16.082,11 MB | L10: Windows 11:10:0:0 | M10: Estación de trabajo | N10: Buencafe_Fabrica | O10: 11.9.100.182 | P10: C475ABC992B2 | Q10: Desactivado
A11: 7426BMO | B11: ADMI08 | C11: pinsdep | D11: 23/12/25 12:24:14 COT | E11: 192.168.41.59 | F11: LENOVO | G11: Tipo de SO:Windows 10,Plataforma de SO:Workstation,Versión de SO:10.0 | H11: 224126 MB | I11: Intel(R) Core(TM) i7-3667U CPU @ 2.00GHz | J11: 04Y1988 | K11: 8.010,84 MB | L11: Windows 10:10:0:0 | M11: Estación de trabajo | N11: Buencafe_Fabrica | O11: 11.9.100.182 | P11: 00B56D011CDB | Q11: Desactivado
A12: R90L7HJP | B12: ADMI09 | C12: SOLAYA948 | D12: 19/12/25 12:32:28 COT | E12: 192.168.40.63 | F12: LENOVO | G12: Tipo de SO:Windows 10,Plataforma de SO:Workstation,Versión de SO:10.0 | H12: 242920 MB | I12: Intel(R) Core(TM) i7-6500U CPU @ 2.50GHz | J12: 20FCS0P100 | K12: 8.063,61 MB | L12: Windows 10:10:0:0 | M12: Estación de trabajo | N12: Buencafe_Fabrica | O12: 11.9.100.182 | P12: 52FBA0888247 | Q12: Desactivado
... A39: NXHN2AL00S1160D7EE7600 | B39: ADMIN | C39: casan | D39: 16/10/25 10:39:43 COT | E39: 192.168.91.22 | F39: Acer | G39: Tipo de SO:Windows 11,Plataforma de SO:Workstation,Versión de SO:10.0 | H39: 243056 MB | I39: Intel(R) Core(TM) i3-10110U CPU @ 2.10GHz | J39: Aspire A515-54 | K39: 20.302,99 MB | L39: Windows 11:10:0:0 | M39: Estación de trabajo | N39: Comite Santander | O39: 11.11.2.1172 | P39: E02BE97DDA2A | Q39: Activada
A40: MP2ABAF | B40: ADMINISTRATIVOS | C40: Administrativo | D40: 22/12/25 13:21:19 COT | E40: 192.168.1.103 | F40: LENOVO | G40: Tipo de SO:Windows 7,Plataforma de SO:Workstation,Versión de SO:6.1 | H40: 114370 MB | I40: Intel(R) Core(TM) i5-3210M CPU @ 2.50GHz | J40: 32543XS | K40: 3.186,86 MB | L40: Windows 7:6:1:0 | M40: Estación de trabajo | N40: Comite Cundinamarca | P40: B888E3E76477 | Q40: Desactivado
A41: PF4F354Q | B41: ADMINOMINA | C41: auxnom2 | D41: 23/12/25 12:27:17 COT | E41: 192.168.207.55 | F41: LENOVO | G41: Tipo de SO:Windows 11,Plataforma de SO:Workstation,Versión de SO:10.0 | H41: 486108 MB | I41: 12th Gen Intel(R) Core(TM) i7-1255U | J41: 21E40023LM | K41: 16.059,65 MB | L41: Windows 11:10:0:0 | M41: Estación de trabajo | N41: Buencafe_Fabrica | O41: 11.9.100.182 | P41: 745D22118C92 | Q41: Desactivado
A42: 3872JS3 | B42: AGROFORESTERIA0 | C42: Dolly Garcia | D42: 21/12/25 12:55:59 COT | E42: 192.168.101.13 | F42: Dell Inc. | G42: Tipo de SO:Windows 11,Plataforma de SO:Workstation,Versión de SO:10.0 | H42: 952979 MB | I42: 13th Gen Intel(R) Core(TM) i5-1335U | J42: Latitude 3440 | K42: 7.876,70 MB | L42: Windows 11:10:0:0 | M42: Estación de trabajo | N42: Comite Nariño | O42: 11.11.2.1172 | P42: 10F60A8D4960 | Q42: Desactivado
A43: 2PH8793 | B43: AGROKMORENO | C43: N/A | D43: 18/12/25 14:38:48 COT | E43: 192.168.20.141 | F43: Dell Inc. | G43: Tipo de SO:Windows 11,Plataforma de SO:Workstation,Versión de SO:10.0 | H43: 2393052 MB | I43: Intel(R) Core(TM) i7-10750H CPU @ 2.60GHz | J43: Precision 3551 | K43: 16.017,86 MB | L43: Windows 11:10:0:0 | M43: Estación de trabajo | N43: Comite Valle | O43: 11.11.2.1172 | P43: 18473DE9C155 | Q43: Desactivado
A44: MJ0M0CLL | B44: AGUADAS01 | C44: Alm. Cafe Aguadas01 | D44: 23/12/25 12:14:14 COT | E44: ########## | F44: LENOVO | G44: Tipo de SO:Windows 11,Plataforma de SO:Workstation,Versión de SO:10.0 | H44: 486107 MB | I44: 13th Gen Intel(R) Core(TM) i5-13400T | J44: 12E4S8PL00 | K44: 16.023,16 MB | L44: Windows 11:10:0:0 | M44: Estación de trabajo | N44: Comite Caldas | O44: 11.11.2.1172 | P44: 250410000000000 | Q44: Desactivado
A45: MP15GMRC | B45: AGUADAS02 | C45: Alm.Cafe Aguadas2 | D45: 23/12/25 12:20:46 COT | E45: 10.11.1.14 | F45: LENOVO | G45: Tipo de SO:Windows 10,Plataforma de SO:Workstation,Versión de SO:10.0 | H45: 921258 MB | I45: Intel(R) Core(TM) i5-7400T CPU @ 2.40GHz | J45: F0CD00GNLD | K45: 8.103,46 MB | L45: Windows 10:10:0:0 | M45: Estación de trabajo | N45: Comite Caldas | O45: 11.11.2.1172 | P45: FC45967BE51B | Q45: Desactivado
A46: BRC4064EPF | B46: alarmlnx | C46: N/A | D46: 28/07/25 11:08:21 COT | E46: 192.168.140.64 | F46: HP | G46: Tipo de SO:Linux,Plataforma de SO:Workstation,Versión de SO:2.6,Versión de Service Pack de SO:32-504.el6.x86_64 | H46: 4500801 MB | I46: Intel(R) Xeon(R) CPU E3-1240 v3 @ 3.40GHz | J46: ProLiant ML310e Gen8 v2 | K46: 7.703,11 MB | L46: LINUX | M46: Estación de trabajo | N46: SERVIDORES | P46: C4346B2111AC | Q46: Desactivado
A47: BRC4064ELW | B47: alboglnx | C47: N/A | D47: 17/09/25 16:26:02 COT | E47: 192.168.24.215 | F47: HP | G47: Tipo de SO:Linux,Plataforma de SO:Workstation,Versión de SO:2.6,Versión de Service Pack de SO:32-504.el6.x86_64 | H47: 1881159 MB | I47: Intel(R) Xeon(R) CPU E3-1240 v3 @ 3.40GHz | J47: ProLiant ML310e Gen8 v2 | K47: 7.956,11 MB | L47: LINUX | M47: Estación de trabajo | N47: Almacafe Bogota-Soacha | P47: E0071B1B7FEC | Q47: Desactivado
A48: BRC4064ELN | B48: albuclnx | C48: N/A | D48: 1/07/25 10:27:45 COT | E48: 192.168.161.64 | F48: HP | G48: Tipo de SO:Linux,Plataforma de SO:Workstation,Versión de SO:2.6,Versión de Service Pack de SO:32-504.el6.x86_64 | H48: 4027072 MB | I48: Intel(R) Xeon(R) CPU E3-1240 v3 @ 3.40GHz | J48: ProLiant ML310e Gen8 v2 | K48: 7.703,11 MB | L48: LINUX | M48: Estación de trabajo | N48: Linux Almacafe | P48: A01D4897061C | Q48: Desactivado
A49: BRC4064EN5 | B49: albuelnx | C49: root | D49: 3/09/25 7:18:40 COT | E49: 192.168.30.64 | F49: HP | G49: Tipo de SO:Linux,Plataforma de SO:Workstation,Versión de SO:2.6,Versión de Service Pack de SO:32-754.el6.x86_64 | H49: 4867689 MB | I49: Intel(R) Xeon(R) CPU E3-1240 v3 @ 3.40GHz | J49: ProLiant ML310e Gen8 v2 | K49: 7.702,31 MB | L49: LINUX | M49: Estación de trabajo | N49: Almacafe Buenaventura | P49: A01D489704BC | Q49: Desactivado
A50: BRC4064EP9 | B50: albuglnx | C50: N/A | D50: 8/08/25 13:31:18 COT | E50: 192.168.155.64 | F50: HP | G50: Tipo de SO:Linux,Plataforma de SO:Workstation,Versión de SO:2.6,Versión de Service Pack de SO:32-504.el6.x86_64 | H50: 4178262 MB | I50: Intel(R) Xeon(R) CPU E3-1240 v3 @ 3.40GHz | J50: ProLiant ML310e Gen8 v2 | K50: 7.703,11 MB | L50: LINUX | M50: Estación de trabajo | N50: Almacafe Buga | P50: A01D489705B4 | Q50: Desactivado
A51: BRC4064ERC | B51: alcarlnx | C51: N/A | D51: 29/08/25 14:17:45 COT | E51: 192.168.35.64 | F51: HP | G51: Tipo de SO:Linux,Plataforma de SO:Workstation,Versión de SO:2.6,Versión de Service Pack de SO:32-754.el6.x86_64 | H51: 4546162 MB | I51: Intel(R) Xeon(R) CPU E3-1240 v3 @ 3.40GHz | J51: ProLiant ML310e Gen8 v2 | K51: 7.702,31 MB | L51: LINUX | M51: Estación de trabajo | N51: Almacafe Cartagena | P51: A01D48970294 | Q51: Desactivado
A52: BRC4064EMH | B52: alcuclnx | C52: N/A | D52: 23/07/25 14:25:02 COT | E52: 192.168.165.64 | F52: HP | G52: Tipo de SO:Linux,Plataforma de SO:Workstation,Versión de SO:2.6,Versión de Service Pack de SO:32-754.el6.x86_64 | H52: 3978691 MB | I52: Intel(R) Xeon(R) CPU E3-1240 v3 @ 3.40GHz | J52: ProLiant ML310e Gen8 v2 | K52: 7.702,31 MB | L52: LINUX | M52: Estación de trabajo | N52: Almacafe Cucuta | P52: A01D48971600 | Q52: Desactivado
A53: PF3YE3E6 | B53: ALEXANDERRANGEL | C53: Alexander Rangel | D53: 23/12/25 12:42:57 COT | E53: 192.168.90.15 | F53: LENOVO | G53: Tipo de SO:Windows 11,Plataforma de SO:Workstation,Versión de SO:10.0 | H53: 974483 MB | I53: 11th Gen Intel(R) Core(TM) i7-11800H @ 2.30GHz | J53: 21AAS06E00 | K53: 16.103,05 MB | L53: Windows 11:10:0:0 | M53: Estación de trabajo | N53: Directory | P53: 6C2408E193D5 | Q53: Desactivado
A54: 5L27XV3 | B54: ALEXBTENAPAYACA | C54: MMARCHCUN | D54: 18/12/25 16:33:27 COT | E54: ########## | F54: Dell Inc. | G54: Tipo de SO:Windows 11,Plataforma de SO:Workstation,Versión de SO:10.0 | H54: 485371 MB | I54: 13th Gen Intel(R) Core(TM) i5-13500T | J54: OptiPlex Micro 7010 | K54: 16.072,73 MB | L54: Windows 11:10:0:0 | M54: Estación de trabajo | N54: Comite Cundinamarca | O54: 11.11.2.1172 | P54: 7497797FBB97 | Q54: Desactivado
A55: BRC4064ELP | B55: alibalnx | C55: N/A | D55: 5/08/25 14:19:22 COT | E55: 192.168.145.64 | F55: HP | G55: Tipo de SO:Linux,Plataforma de SO:Workstation,Versión de SO:2.6,Versión de Service Pack de SO:32-504.el6.x86_64 | H55: 4480642 MB | I55: Intel(R) Xeon(R) CPU E3-1240 v3 @ 3.40GHz | J55: ProLiant ML310e Gen8 v2 | K55: 7.703,11 MB | L55: LINUX | M55: Estación de trabajo | N55: SERVIDORES | P55: A0481CD6F3C4 | Q55: Desactivado
A56: BRC4064EN4 | B56: almedlnx | C56: N/A | D56: 4/09/25 9:28:13 COT | E56: 192.168.126.64 | F56: HP | G56: Tipo de SO:Linux,Plataforma de SO:Workstation,Versión de SO:2.6,Versión de Service Pack de SO:32-754.el6.x86_64 | H56: 4752783 MB | I56: Intel(R) Xeon(R) CPU E3-1240 v3 @ 3.40GHz | J56: ProLiant ML310e Gen8 v2 | K56: 7.702,31 MB | L56: LINUX | M56: Estación de trabajo | N56: Linux Almacafe | P56: A01D48971778 | Q56: Desactivado
A57: BRC4064ERB | B57: almmanizaleslnx | C57: N/A | D57: 23/07/25 14:45:36 COT | E57: 192.168.130.11 | F57: HP | G57: Tipo de SO:Linux,Plataforma de SO:Workstation,Versión de SO:2.6,Versión de Service Pack de SO:32-504.el6.x86_64 | H57: 5549943 MB | I57: Intel(R) Xeon(R) CPU E3-1240 v3 @ 3.40GHz | J57: ProLiant ML310e Gen8 v2 | K57: 7.703,11 MB | L57: LINUX | M57: Estación de trabajo | N57: SERVIDORES | P57: A01D48971688 | Q57: Desactivado
A58: BRC4064ELY | B58: alneilnx | C58: N/A | D58: 6/08/25 16:25:55 COT | E58: 192.168.150.64 | F58: HP | G58: Tipo de SO:Linux,Plataforma de SO:Workstation,Versión de SO:2.6,Versión de Service Pack de SO:32-754.el6.x86_64 | H58: 5629194 MB | I58: Intel(R) Xeon(R) CPU E3-1240 v3 @ 3.40GHz | J58: ProLiant ML310e Gen8 v2 | K58: 7.831,31 MB | L58: LINUX | M58: Estación de trabajo | N58: SERVIDORES | P58: 40A8F0C7AE74 | Q58: Desactivado
A59: BRC4064EN0 | B59: alpaslnx | C59: N/A | D59: 6/08/25 9:24:09 COT | E59: 192.168.175.64 | F59: HP | G59: Tipo de SO:Linux,Plataforma de SO:Workstation,Versión de SO:2.6,Versión de Service Pack de SO:32-754.el6.x86_64 | H59: 4842724 MB | I59: Intel(R) Xeon(R) CPU E3-1240 v3 @ 3.40GHz | J59: ProLiant ML310e Gen8 v2 | K59: 7.955,30 MB | L59: LINUX | M59: Estación de trabajo | N59: Linux Almacafe | P59: A01D489717EC | Q59: Desactivado
A60: BRC4064ERA | B60: ALPERLNX | C60: N/A | D60: 15/08/25 13:37:09 COT | E60: 192.168.135.64 | F60: HP | G60: Tipo de SO:Linux,Plataforma de SO:Workstation,Versión de SO:2.6,Versión de Service Pack de SO:32-754.el6.x86_64 | H60: 4034128 MB | I60: Intel(R) Xeon(R) CPU E3-1240 v3 @ 3.40GHz | J60: ProLiant ML310e Gen8 v2 | K60: 7.702,31 MB | L60: LINUX | M60: Estación de trabajo | N60: Linux Almacafe | P60: A0481CD6F3FC | Q60: Desactivado
A61: BRC4064EN8 | B61: alpoplnx | C61: N/A | D61: 4/09/25 10:55:20 COT | E61: 192.168.170.64 | F61: HP | G61: Tipo de SO:Linux,Plataforma de SO:Workstation,Versión de SO:2.6,Versión de Service Pack de SO:32-754.el6.x86_64 | H61: 4077469 MB | I61: Intel(R) Xeon(R) CPU E3-1240 v3 @ 3.40GHz | J61: ProLiant ML310e Gen8 v2 | K61: 7.702,31 MB | L61: LINUX | M61: Estación de trabajo | N61: Linux Almacafe | P61: A01D489705AC | Q61: Desactivado
A62: BRC4064ELL | B62: alsanlnx | C62: N/A | D62: 23/07/25 14:42:54 COT | E62: 192.168.180.64 | F62: HP | G62: Tipo de SO:Linux,Plataforma de SO:Workstation,Versión de SO:2.6,Versión de Service Pack de SO:32-754.el6.x86_64 | H62: 4833162 MB | I62: Intel(R) Xeon(R) CPU E3-1240 v3 @ 3.40GHz | J62: ProLiant ML310e Gen8 v2 | K62: 7.702,31 MB | L62: LINUX | M62: Estación de trabajo | N62: Linux Almacafe | P62: A0481CD6FB0C | Q62: Desactivado
A63: 8CN12500BV | B63: ANALISTAFINANCI | C63: User | D63: 19/12/25 8:53:10 COT | E63: 192.168.90.94 | F63: HP | G63: Tipo de SO:Windows 10,Plataforma de SO:Workstation,Versión de SO:10.0 | H63: 476298 MB | I63: Intel(R) Core(TM) i5-10500 CPU @ 3.10GHz | J63: HP ProOne 400 G6 20 All-in-One PC | K63: 7.967,22 MB | L63: Windows 10:10:0:0 | M63: Estación de trabajo | N63: Comite Santander | O63: 11.11.2.1172 | P63: 489EBDD59EDA | Q63: Desactivado
A64: MJ04PGVN | B64: ANALIZADOR | C64: analizador | D64: 23/12/25 12:16:33 COT | E64: 192.168.41.74 | F64: LENOVO | G64: Tipo de SO:Windows 10,Plataforma de SO:Workstation,Versión de SO:10.0 | H64: 952591 MB | I64: Intel(R) Xeon(R) CPU E3-1225 v5 @ 3.30GHz | J64: 30ASA0DN00 | K64: 8.082,21 MB | L64: Windows 10:10:0:0 | M64: Estación de trabajo | N64: Buencafe_Fabrica | O64: 11.9.100.182 | P64: 4CCC6A741023 | Q64: Desactivado
A65: NXVU2AL00123210F8B3400 | B65: ANDREAJFUYA | C65: N/A | D65: 17/12/25 17:29:52 COT | E65: 192.168.100.50 | F65: Acer | G65: Tipo de SO:Windows 11,Plataforma de SO:Workstation,Versión de SO:10.0 | H65: 487083 MB | I65: 11th Gen Intel(R) Core(TM) i5-1155G7 @ 2.50GHz | J65: TravelMate V15-51 | K65: 20.259,30 MB | L65: Windows 11:10:0:0 | M65: Estación de trabajo | N65: Comite Santander | O65: 11.11.2.1172 | P65: E0D045F47FF9 | Q65: Desactivado
A66: NXVU2AL00123300AEB3400 | B66: ANGELOGUERRERO | C66: giovany guerrero | D66: 18/12/25 16:29:18 COT | E66: 192.168.1.67 | F66: Acer | G66: Tipo de SO:Windows 11,Plataforma de SO:Workstation,Versión de SO:10.0 | H66: 487083 MB | I66: 11th Gen Intel(R) Core(TM) i5-1155G7 @ 2.50GHz | J66: TravelMate V15-51 | K66: 20.259,30 MB | L66: Windows 11:10:0:0 | M66: Estación de trabajo | N66: Comite Cauca | O66: 11.11.2.1172 | P66: E0D045F72DB7 | Q66: Desactivado
...

Sheet Equipo en Estado Baja
A1: EMPRESA PROPIETARIO DEL EQUIPO | B1: DEPENDENCIA | C1: FUENTE DE RECURSO | D1: EMPRESA FUNCIONARIO | E1: CEDULA DEL FUNCIONARIO | F1: SHORTNAME | G1: NOMBRES Y APELLIDOS | H1: CARGO | I1: ÁREA | J1: UBICACIÓN Y PISO | K1: TIPO | L1: SERIAL | M1: PLACA | N1: MARCA | O1: MODELO | P1: NOMBRE DE EQUIPO | Q1: ESTADO OPERATIVO | R1: RAZÓN DEL ESTADO | S1: ADMINISTRADO/CONTROLADO | T1: PROCESADOR | U1: MEMORIA RAM | V1: TAMAÑO DISCO DURO | W1: SISTEMA OPERATIVO | X1: FECHA DE COMPRA | Y1: FIN DE GARANTIA | Z1: TIEMPO USO (AÑOS) | AA1: TIPO DE PROPIEDAD | AB1: CHEKLIST (RESPONSABLE TI) | AC1: ORDEN DE REMISIÓN

Sheet Listas De Validación Equipos 
A1: EMPRESA PROPIETARIO DEL EQUIPO | C1: DEPENDENCIA | E1: FUENTE DE RECURSO | G1: EMPRESA DE FUNCIONARIO | I1: TIPO | K1: ESTADO | L1: DESCRIPCIÓN DEL ESTADO | M1: RAZÓN DEL ESTADO | N1: DESCRIPCIÓN DEL RAZÓN DEL ESTADO | P1: ADMINISTRADO/CONTROLADO | R1: PROCESADOR | T1: MEMORIA RAM | V1: TAMAÑO DISCO DURO | X1: SISTEMA OPERATIVO
A2: ALMACAFÉ | C2: AGENCIA CUCUTA | E2: FON1 | G2: ALMACAFÉ | I2: EQUIPO ESCRITORIO | K2: ALMACENADO | L2: TODO ACTIVO QUE SE ENCUENTRA RESERVADO EN UNA BODEGA. | M2: DISPONIBLE | N2: TODO ACTIVO QUE SE ENCUENTRE DISPONIBLE NUEVO O USADO PARA ASIGNACIÓN A USUARIO FINAL. | P2: ADMINISTRADO | R2: 11TH GEN INTEL(R) CORE(TM) I3-1115G4 @ 3.00GHZ | T2: 12GB | V2: 120GB | X2: ANDROID
A3: FEDERACIÓN | C3: AGENCIA PASTO | E3: FON2 | G3: FEDERACIÓN | I3: EQUIPO PORTATIL | K3: TRÁNSITO | L3: TODO ACTIVO QUE SE ENCUENTRA EN CIRCULACIÓN. | M3: CUSTODIA | N3: TODO ACTIVO QUE INGRESE A BODEGA ESTARÁ ALMACENADO 15 DÍAS HÁBILES, DESPÚES DE ESTE TIEMPO SE REALIZARÁ EL CAMBIO DE ESTADO A DISPONIBLE PARA SU ASIGNACIÓN SEGÚN SE REQUIERA. | P3: CONTROLADO | R3: 11TH GEN INTEL(R) CORE(TM) I5-1135G7 @ 2.40GHZ | T3: 16GB | V3: 128GB | X3: IOS
A4: BANCOLOMBIA | C4: AGENCIA POPAYAN | E4: FEPC | G4: TIVIT | I4: EQUIPO TODO EN UNO | K4: EN OPERACIÓN | L4: TODO ACTIVO QUE SE ENCUENTRA EN USO POR PARTE DE UN COLABORADOR. | M4: ALISTAMIENTO / SOPORTE | N4: TODOS AQUELLOS ACTIVOS QUE SE ENCUENTREN EN PROCESO DE ALISTAMIENTO, MANTENIMIENTO, SOPORTE O GARANTÍA | R4: 11TH GEN INTEL(R) CORE(TM) I5-11400 @ 2.60GHZ | T4: 1GB | V4: 16GB | X4: LINUX
A5: CAFECERT | C5: BUENCAFÉ | E5: ALMACAFÉ | G5: SAMTEL | I5: IMPRESORA | K5: BAJA | L5: TODO ACTIVO QUE SE ENCUENTRA EN PROCESO PARA DISPOCISIÓN FINAL. | M5: RENOVACIÓN | N5: TODO ACTIVO NUEVO QUE INGRESA A BODEGA CON LA FINALIDAD DE REALIZAR LA ACTUALIZACIÓN DE LOS MISMOS. | R5: 11TH GEN INTEL(R) CORE(TM) I5-11400T @ 1.30GHZ | T5: 20GB | V5: 180GB | X5: MACOS BIG SUR
M6: PROCESAR BAJA | N6: TODO ACTIVO QUE SE ENCUENTRA EN PEL PROCESO DE BAJA. | R6: No Aplica | T6: No Aplica | V6: No Aplica | X6: No Aplica
A7: FONDO NACIONAL | C7: CENICAFÉ | G7: TECNOFILE | I7: TABLETA | K7: HURTO | L7: TODO ACTIVO HURTADO. | M7: DESPACHO | N7: TODO ACTIVO QUE SE ENCUENTRA EN MOVIMIENTO O TRASLADO DESDE LA OFICINA BOGOTÁ PARA LAS SEDES, COMITES E INSPECCIONES A NIVEL NACIONAL. | R7: 11TH GEN INTEL(R) CORE(TM) I5-1145G7 @ 2.60GHZ | T7: 24GB | V7: 1TB | X7: MACOS CATALINA
C8: COMITÉ ANTIOQUIA | I8: ESANER | M8: RETORNO | N8: TODO ACTIVO QUE SE ENCUENTRA EN MOVIMIENTO O TRASLADO DESDE SEDES,COMITÉS Ó INSPECCIONES A NIVEL NACIONAL QUE SEAN ENVIADOS A LA OFICINA BOGOTÁ. | R8: 11TH GEN INTEL(R) CORE(TM) I5-1155G7 @ 2.50GHZ | T8: 2GB | V8: 1TB + 500GB | X8: MACOS MONTEREY
